<mujoco model="RPR_robot">
    <option gravity="0 0 0" integrator="RK4" timestep="0.01"/>
        

    <worldbody>
      <body name = 'ground' pos='0 0 0'>
        <geom type='box' size ="10 10 0.01"/>
      </body>  
    
        <body name='robot' pos='0 0 .1'>
        <joint name='R_1' limited='true' range='-60 60'/>

            <body name='base' pos='0 0 0'>
                <geom name='base' type='cylinder' size='1 .5' rgba=".9 .1 .1 1" pos='0 0 .5'/>

                <body name='link_1' pos='0 0 5'>
                    <geom name='link1' type='box' size='.3 .3 5' rgba=".2 .2 .9 1"/>
                    
                    <body name='connector' pos='0 .5 5'>
                        <joint name='R_2' axis='0 1 0' limited='true' range='-70 70'/>
                        <geom type='cylinder' size='1 1' rgba=".9 .1 .1 1"  euler='90 0 0'/>

                        <body name='link_2' pos='0 .5 0'>
                            <joint name='P_1' type='slide' axis='1 0 0' range="-4 5" limited="true"/>
                            <geom type='box' size='.3 .3 5' rgba=".2 .2 .9 1"  euler='0 90 0 '/>
                            <site name='end_effector' pos="5 0 0" size='.7' rgba='.1 .9 .1 1'/>
                        </body>

                    </body>
                
                </body>
 
            </body>
        </body>
        <site name='goal' pos='12 0 10'size='.6' rgba=".9 .1 .1 1"/>

    </worldbody>

    <actuator>
        <motor name='R_1' joint='R_1' ctrllimited="true" ctrlrange="-1.0 1.0" gear="500000"/> 
        <motor name='R_2' joint='R_2' ctrllimited="true" ctrlrange="-1.0 1.0" gear="500000"/>
        <motor name='P_1' joint='P_1' ctrllimited="true" ctrlrange="-1.0 1.0" gear="500000"/>  
    </actuator>


</mujoco>

